2018-04-10 11:54:05,423 - ERROR - 1. 接口编号 : 4_1 | 接口名称 : Space - 空间列表 
2018-04-10 11:54:05,423 - ERROR - 2. 检查信息 : 测试机构1=[3][name] | 实际返回结果:测试机构 
2018-04-10 11:54:05,424 - ERROR - 3. 错误信息 : Traceback (most recent call last):
  File "/Users/xiaojingyuan/PycharmProjects/Appium/YunluFramework_API/testcase/SpaceAPI/TestSpaceApi.py", line 169, in test_api
    assert False != api_check_result[0]
AssertionError

2018-04-10 13:52:17,074 - ERROR - 1. 接口编号 : 4_1 | 接口名称 : Space - 空间列表 
2018-04-10 13:52:17,074 - ERROR - 2. 检查信息 : 测试机构1=[3][name] | 实际返回结果:测试机构 
2018-04-10 13:52:17,074 - ERROR - 3. 错误信息 : Traceback (most recent call last):
  File "/Users/xiaojingyuan/PycharmProjects/Appium/YunluFramework_API/testcase/SpaceAPI/TestSpaceApi.py", line 169, in test_api
    assert False != api_check_result[0]
AssertionError

